Workbook

Sheet Company Data
A1: Module 2 — 12-company data
A3: Company | B3: Walmart | C3: Target | D3: Costco | E3: Home Depot | F3: Lowe’s | G3: Nike | H3: Coca-Cola | I3: PepsiCo | J3: Procter & Gamble | K3: Starbucks | L3: YUM! Brands | M3: Delta Air Lines
A4: Ticker | B4: WMT | C4: TGT | D4: COST | E4: HD | F4: LOW | G4: NKE | H4: KO | I4: PEP | J4: PG | K4: SBUX | L4: YUM | M4: DAL
A5: Current annual period | B5: 46053 | C5: 46053 | D5: 45900 | E5: 46053 | F5: 46053 | G5: 46173 | H5: 46022 | I5: 46022 | J5: 46203 | K5: 45930 | L5: 46022 | M5: 46022
A6: Revenue ($m) | B6: 713163 | C6: 104780 | D6: 275235 | E6: 164683 | F6: 86286 | G6: 46398 | H6: 47941 | I6: 93925 | J6: 87032 | K6: 37184.4 | L6: 8214 | M6: 63364
A7: Net income ($m) | B7: 21893 | C7: 3705 | D7: 8099 | E7: 14156 | F7: 6654 | G7: 3108 | H7: 13107 | I7: 8240 | J7: 16046 | K7: 1856.4 | L7: 1559 | M7: 5005
A8: Basic EPS ($/share) | B8: 2.74 | C8: 8.16 | D8: 18.24 | E8: 14.26 | F8: 11.87 | G8: 2.1 | H8: 3.05 | I8: 6.026299 | J8: 6.75 | K8: 1.632861 | L8: 5.59 | M8: 7.720031
A9: Shares outstanding (m) | B9: 7969 | C9: 452.84019 | D9: 443.237 | E9: 995.51148 | F9: 560.95146 | G9: 1483.4987 | H9: 4301.6088 | I9: 1367.3401 | J9: 2323.859 | K9: 1136.9 | L9: 276.56949 | M9: 653.17124
A10: Total assets ($m) | B10: 284668 | C10: 59490 | D10: 77099 | E10: 105095 | F10: 54144 | G10: 38410 | H10: 104816 | I10: 107399 | J10: 126521 | K10: 32019.7 | L10: 8197 | M10: 81317
A11: EBIT ($m) | B11: 32268 | C11: 5212 | D11: 10972 | E11: 21014 | F11: 10274 | G11: 3797 | H11: 17652 | I11: 11365 | J11: 21254 | K11: 3049.9 | L11: 2578 | M11: 6864
A12: Net PP&E ($m) | B12: 156956 | C12: 37452 | D12: 34634 | E12: 37225 | F12: 22665 | G12: 7634 | H12: 9613 | I12: 33650 | J12: 25360 | K12: 17809.2 | L12: 2818 | M12: 45987
A13: Current assets ($m) | B13: 84874 | C13: 20005 | D13: 38380 | E13: 34391 | F13: 20955 | G13: 24603 | H13: 31044 | I13: 27949 | J13: 26208 | K13: 7382.3 | L13: 2040 | M13: 10968
A14: Current liabilities ($m) | B14: 107469 | C14: 21230 | D14: 37108 | E14: 32424 | F14: 19463 | G14: 12547 | H14: 21281 | I14: 32764 | J14: 38694 | K14: 10210.4 | L14: 1516 | M14: 27624
A15: Stockholders’ equity ($m) | B15: 99617 | C15: 16165 | D15: 29164 | E15: 12813 | F15: -9917 | G15: 14865 | H15: 32169 | I15: 20406 | J15: 54081 | K15: -8096.6 | L15: -7325 | M15: 20853
A16: Pretax income ($m) | B16: 29469 | C16: 4767 | D16: 10818 | E16: 18602 | F16: 8747 | G16: 3900 | H16: 15998 | I16: 10244 | J16: 20377 | K16: 2507.3 | L16: 2077 | M16: 6185
... A32: Tax provision ($m) | B32: 6152 | C32: 1170 | D32: 2373 | E32: 4600 | F32: 2196 | G32: 666 | H32: 2437 | I32: 2320 | J32: 4102 | K32: 1207.3 | L32: 414 | M32: 1201

Sheet YoY Changes
A1: Module 2 — year-over-year changes
A3: Company | B3: Walmart | C3: Target | D3: Costco | E3: Home Depot | F3: Lowe’s | G3: Nike | H3: Coca-Cola | I3: PepsiCo | J3: Procter & Gamble | K3: Starbucks | L3: YUM! Brands | M3: Delta Air Lines
A4: Ticker | B4: WMT | C4: TGT | D4: COST | E4: HD | F4: LOW | G4: NKE | H4: KO | I4: PEP | J4: PG | K4: SBUX | L4: YUM | M4: DAL
A5: Change: current − prior
A6: Revenue ($m) | B6: ='Company Data'!B6-'Company Data'!B21 -> 32178 | C6: ='Company Data'!C6-'Company Data'!C21 -> -1786 | D6: ='Company Data'!D6-'Company Data'!D21 -> 20782 | E6: ='Company Data'!E6-'Company Data'!E21 -> 5169 | F6: ='Company Data'!F6-'Company Data'!F21 -> 2612 | G6: ='Company Data'!G6-'Company Data'!G21 -> 89 | H6: ='Company Data'!H6-'Company Data'!H21 -> 880 | I6: ='Company Data'!I6-'Company Data'!I21 -> 2071 | ... M6: ='Company Data'!M6-'Company Data'!M21 -> 1721
A7: Net income ($m) | B7: ='Company Data'!B7-'Company Data'!B22 -> 2457 | C7: ='Company Data'!C7-'Company Data'!C22 -> -386 | D7: ='Company Data'!D7-'Company Data'!D22 -> 732 | E7: ='Company Data'!E7-'Company Data'!E22 -> -650 | F7: ='Company Data'!F7-'Company Data'!F22 -> -303 | G7: ='Company Data'!G7-'Company Data'!G22 -> -111 | H7: ='Company Data'!H7-'Company Data'!H22 -> 2476 | I7: ='Company Data'!I7-'Company Data'!I22 -> -1338 | ... M7: ='Company Data'!M7-'Company Data'!M22 -> 1548
A8: Basic EPS ($/share) | B8: ='Company Data'!B8-'Company Data'!B23 -> 0.32 | C8: ='Company Data'!C8-'Company Data'!C23 -> -0.73 | D8: ='Company Data'!D8-'Company Data'!D23 -> 1.65 | E8: ='Company Data'!E8-'Company Data'!E23 -> -0.7 | F8: ='Company Data'!F8-'Company Data'!F23 -> -0.38 | G8: ='Company Data'!G8-'Company Data'!G23 -> -0.07 | H8: ='Company Data'!H8-'Company Data'!H23 -> 0.58 | I8: ='Company Data'!I8-'Company Data'!I23 -> -0.954806 | ... M8: ='Company Data'!M8-'Company Data'!M23 -> 2.330009
A9: Shares outstanding (m) | B9: ='Company Data'!B9-'Company Data'!B24 -> -55 | C9: ='Company Data'!C9-'Company Data'!C24 -> -2.726808 | D9: ='Company Data'!D9-'Company Data'!D24 -> 0.111 | E9: ='Company Data'!E9-'Company Data'!E24 -> 1.511485 | F9: ='Company Data'!F9-'Company Data'!F24 -> 0.951457 | G9: ='Company Data'!G9-'Company Data'!G24 -> 7.498703 | H9: ='Company Data'!H9-'Company Data'!H24 -> -0.391155 | I9: ='Company Data'!I9-'Company Data'!I24 -> -4.648903 | ... M9: ='Company Data'!M9-'Company Data'!M24 -> 6.698602
A10: Total assets ($m) | B10: ='Company Data'!B10-'Company Data'!B25 -> 23845 | C10: ='Company Data'!C10-'Company Data'!C25 -> 1721 | D10: ='Company Data'!D10-'Company Data'!D25 -> 7268 | E10: ='Company Data'!E10-'Company Data'!E25 -> 8976 | F10: ='Company Data'!F10-'Company Data'!F25 -> 11042 | G10: ='Company Data'!G10-'Company Data'!G25 -> 1831 | H10: ='Company Data'!H10-'Company Data'!H25 -> 4267 | I10: ='Company Data'!I10-'Company Data'!I25 -> 7932 | ... M10: ='Company Data'!M10-'Company Data'!M25 -> 5945
A11: EBIT ($m) | B11: ='Company Data'!B11-'Company Data'!B26 -> 3231 | C11: ='Company Data'!C11-'Company Data'!C26 -> -460 | D11: ='Company Data'!D11-'Company Data'!D26 -> 1063 | E11: ='Company Data'!E11-'Company Data'!E26 -> -713 | F11: ='Company Data'!F11-'Company Data'!F26 -> -351 | G11: ='Company Data'!G11-'Company Data'!G26 -> 95 | H11: ='Company Data'!H11-'Company Data'!H26 -> 2910 | I11: ='Company Data'!I11-'Company Data'!I26 -> -1500 | ... M11: ='Company Data'!M11-'Company Data'!M26 -> 1459
A12: Net PP&E ($m) | B12: ='Company Data'!B12-'Company Data'!B27 -> 17252 | C12: ='Company Data'!C12-'Company Data'!C27 -> 667 | D12: ='Company Data'!D12-'Company Data'!D27 -> 2985 | E12: ='Company Data'!E12-'Company Data'!E27 -> 1931 | F12: ='Company Data'!F12-'Company Data'!F27 -> 1278 | G12: ='Company Data'!G12-'Company Data'!G27 -> 94 | H12: ='Company Data'!H12-'Company Data'!H27 -> -690 | I12: ='Company Data'!I12-'Company Data'!I27 -> 2259 | ... M12: ='Company Data'!M12-'Company Data'!M27 -> 1748
A13: Current assets ($m) | B13: ='Company Data'!B13-'Company Data'!B28 -> 5416 | C13: ='Company Data'!C13-'Company Data'!C28 -> 551 | D13: ='Company Data'!D13-'Company Data'!D28 -> 4134 | E13: ='Company Data'!E13-'Company Data'!E28 -> 2708 | F13: ='Company Data'!F13-'Company Data'!F28 -> 597 | G13: ='Company Data'!G13-'Company Data'!G28 -> 1241 | H13: ='Company Data'!H13-'Company Data'!H28 -> 5047 | I13: ='Company Data'!I13-'Company Data'!I28 -> 2123 | ... M13: ='Company Data'!M13-'Company Data'!M28 -> 1124
A14: Current liabilities ($m) | B14: ='Company Data'!B14-'Company Data'!B29 -> 10885 | C14: ='Company Data'!C14-'Company Data'!C29 -> 431 | D14: ='Company Data'!D14-'Company Data'!D29 -> 1644 | E14: ='Company Data'!E14-'Company Data'!E29 -> 3763 | F14: ='Company Data'!F14-'Company Data'!F29 -> 706 | G14: ='Company Data'!G14-'Company Data'!G29 -> 1981 | H14: ='Company Data'!H14-'Company Data'!H29 -> -3968 | I14: ='Company Data'!I14-'Company Data'!I29 -> 1228 | ... M14: ='Company Data'!M14-'Company Data'!M29 -> 954
A15: Stockholders’ equity ($m) | B15: ='Company Data'!B15-'Company Data'!B30 -> 8604 | C15: ='Company Data'!C15-'Company Data'!C30 -> 1499 | D15: ='Company Data'!D15-'Company Data'!D30 -> 5542 | E15: ='Company Data'!E15-'Company Data'!E30 -> 6173 | F15: ='Company Data'!F15-'Company Data'!F30 -> 4314 | G15: ='Company Data'!G15-'Company Data'!G30 -> 1652 | H15: ='Company Data'!H15-'Company Data'!H30 -> 7313 | I15: ='Company Data'!I15-'Company Data'!I30 -> 2365 | ... M15: ='Company Data'!M15-'Company Data'!M30 -> 5560
A16: Pretax income ($m) | B16: ='Company Data'!B16-'Company Data'!B31 -> 3160 | C16: ='Company Data'!C16-'Company Data'!C31 -> -494 | D16: ='Company Data'!D16-'Company Data'!D31 -> 1078 | E16: ='Company Data'!E16-'Company Data'!E31 -> -804 | F16: ='Company Data'!F16-'Company Data'!F31 -> -406 | G16: ='Company Data'!G16-'Company Data'!G31 -> 15 | H16: ='Company Data'!H16-'Company Data'!H31 -> 2912 | I16: ='Company Data'!I16-'Company Data'!I31 -> -1702 | ... M16: ='Company Data'!M16-'Company Data'!M31 -> 1527
A17: Tax provision ($m) | B17: ='Company Data'!B17-'Company Data'!B32 -> 1047 | C17: ='Company Data'!C17-'Company Data'!C32 -> -108 | D17: ='Company Data'!D17-'Company Data'!D32 -> 346 | E17: ='Company Data'!E17-'Company Data'!E32 -> -154 | F17: ='Company Data'!F17-'Company Data'!F32 -> -103 | G17: ='Company Data'!G17-'Company Data'!G32 -> 126 | H17: ='Company Data'!H17-'Company Data'!H32 -> 424 | I17: ='Company Data'!I17-'Company Data'!I32 -> -371 | ... M17: ='Company Data'!M17-'Company Data'!M32 -> -21
A18: Net working capital ($m) | B18: =('Company Data'!B13-'Company Data'!B14)-('Company Data'!B28-'Company Data'!B29) -> -5469 | C18: =('Company Data'!C13-'Company Data'!C14)-('Company Data'!C28-'Company Data'!C29) -> 120 | D18: =('Company Data'!D13-'Company Data'!D14)-('Company Data'!D28-'Company Data'!D29) -> 2490 | E18: =('Company Data'!E13-'Company Data'!E14)-('Company Data'!E28-'Company Data'!E29) -> -1055 | F18: =('Company Data'!F13-'Company Data'!F14)-('Company Data'!F28-'Company Data'!F29) -> -109 | G18: =('Company Data'!G13-'Company Data'!G14)-('Company Data'!G28-'Company Data'!G29) -> -740 | H18: =('Company Data'!H13-'Company Data'!H14)-('Company Data'!H28-'Company Data'!H29) -> 9015 | I18: =('Company Data'!I13-'Company Data'!I14)-('Company Data'!I28-'Company Data'!I29) -> 895 | ... M18: =('Company Data'!M13-'Company Data'!M14)-('Company Data'!M28-'Company Data'!M29) -> 170
A21: Percentage change
A22: Revenue | B22: =IF('Company Data'!B21<=0,"n/m",('Company Data'!B6-'Company Data'!B21)/'Company Data'!B21) -> 0.047252142 | C22: =IF('Company Data'!C21<=0,"n/m",('Company Data'!C6-'Company Data'!C21)/'Company Data'!C21) -> -0.016759567 | D22: =IF('Company Data'!D21<=0,"n/m",('Company Data'!D6-'Company Data'!D21)/'Company Data'!D21) -> 0.081673236 | E22: =IF('Company Data'!E21<=0,"n/m",('Company Data'!E6-'Company Data'!E21)/'Company Data'!E21) -> 0.032404679 | F22: =IF('Company Data'!F21<=0,"n/m",('Company Data'!F6-'Company Data'!F21)/'Company Data'!F21) -> 0.031216387 | G22: =IF('Company Data'!G21<=0,"n/m",('Company Data'!G6-'Company Data'!G21)/'Company Data'!G21) -> 0.0019218726 | H22: =IF('Company Data'!H21<=0,"n/m",('Company Data'!H6-'Company Data'!H21)/'Company Data'!H21) -> 0.018699135 | I22: =IF('Company Data'!I21<=0,"n/m",('Company Data'!I6-'Company Data'!I21)/'Company Data'!I21) -> 0.02254665 | ... M22: =IF('Company Data'!M21<=0,"n/m",('Company Data'!M6-'Company Data'!M21)/'Company Data'!M21) -> 0.027918823
A23: Net income | B23: =IF('Company Data'!B22<=0,"n/m",('Company Data'!B7-'Company Data'!B22)/'Company Data'!B22) -> 0.1264149 | C23: =IF('Company Data'!C22<=0,"n/m",('Company Data'!C7-'Company Data'!C22)/'Company Data'!C22) -> -0.094353459 | D23: =IF('Company Data'!D22<=0,"n/m",('Company Data'!D7-'Company Data'!D22)/'Company Data'!D22) -> 0.09936202 | E23: =IF('Company Data'!E22<=0,"n/m",('Company Data'!E7-'Company Data'!E22)/'Company Data'!E22) -> -0.043901121 | F23: =IF('Company Data'!F22<=0,"n/m",('Company Data'!F7-'Company Data'!F22)/'Company Data'!F22) -> -0.043553256 | G23: =IF('Company Data'!G22<=0,"n/m",('Company Data'!G7-'Company Data'!G22)/'Company Data'!G22) -> -0.034482759 | H23: =IF('Company Data'!H22<=0,"n/m",('Company Data'!H7-'Company Data'!H22)/'Company Data'!H22) -> 0.23290377 | I23: =IF('Company Data'!I22<=0,"n/m",('Company Data'!I7-'Company Data'!I22)/'Company Data'!I22) -> -0.13969513 | ... M23: =IF('Company Data'!M22<=0,"n/m",('Company Data'!M7-'Company Data'!M22)/'Company Data'!M22) -> 0.4477871
A24: Basic EPS | B24: =IF('Company Data'!B23<=0,"n/m",('Company Data'!B8-'Company Data'!B23)/'Company Data'!B23) -> 0.1322314 | C24: =IF('Company Data'!C23<=0,"n/m",('Company Data'!C8-'Company Data'!C23)/'Company Data'!C23) -> -0.082114736 | D24: =IF('Company Data'!D23<=0,"n/m",('Company Data'!D8-'Company Data'!D23)/'Company Data'!D23) -> 0.099457505 | E24: =IF('Company Data'!E23<=0,"n/m",('Company Data'!E8-'Company Data'!E23)/'Company Data'!E23) -> -0.046791444 | F24: =IF('Company Data'!F23<=0,"n/m",('Company Data'!F8-'Company Data'!F23)/'Company Data'!F23) -> -0.031020408 | G24: =IF('Company Data'!G23<=0,"n/m",('Company Data'!G8-'Company Data'!G23)/'Company Data'!G23) -> -0.032258065 | H24: =IF('Company Data'!H23<=0,"n/m",('Company Data'!H8-'Company Data'!H23)/'Company Data'!H23) -> 0.23481781 | I24: =IF('Company Data'!I23<=0,"n/m",('Company Data'!I8-'Company Data'!I23)/'Company Data'!I23) -> -0.13677004 | ... M24: =IF('Company Data'!M23<=0,"n/m",('Company Data'!M8-'Company Data'!M23)/'Company Data'!M23) -> 0.43228191
A25: Shares outstanding | B25: =IF('Company Data'!B24<=0,"n/m",('Company Data'!B9-'Company Data'!B24)/'Company Data'!B24) -> -0.0068544367 | C25: =IF('Company Data'!C24<=0,"n/m",('Company Data'!C9-'Company Data'!C24)/'Company Data'!C24) -> -0.0059855258 | D25: =IF('Company Data'!D24<=0,"n/m",('Company Data'!D9-'Company Data'!D24)/'Company Data'!D24) -> 0.00025049309 | E25: =IF('Company Data'!E24<=0,"n/m",('Company Data'!E9-'Company Data'!E24)/'Company Data'!E24) -> 0.0015206087 | F25: =IF('Company Data'!F24<=0,"n/m",('Company Data'!F9-'Company Data'!F24)/'Company Data'!F24) -> 0.0016990304 | G25: =IF('Company Data'!G24<=0,"n/m",('Company Data'!G9-'Company Data'!G24)/'Company Data'!G24) -> 0.0050804221 | H25: =IF('Company Data'!H24<=0,"n/m",('Company Data'!H9-'Company Data'!H24)/'Company Data'!H24) -> -9.0923989e-05 | I25: =IF('Company Data'!I24<=0,"n/m",('Company Data'!I9-'Company Data'!I24)/'Company Data'!I24) -> -0.0033884404 | ... M25: =IF('Company Data'!M24<=0,"n/m",('Company Data'!M9-'Company Data'!M24)/'Company Data'!M24) -> 0.010361772
A26: Total assets | B26: =IF('Company Data'!B25<=0,"n/m",('Company Data'!B10-'Company Data'!B25)/'Company Data'!B25) -> 0.091422152 | C26: =IF('Company Data'!C25<=0,"n/m",('Company Data'!C10-'Company Data'!C25)/'Company Data'!C25) -> 0.029791064 | D26: =IF('Company Data'!D25<=0,"n/m",('Company Data'!D10-'Company Data'!D25)/'Company Data'!D25) -> 0.10407985 | E26: =IF('Company Data'!E25<=0,"n/m",('Company Data'!E10-'Company Data'!E25)/'Company Data'!E25) -> 0.093384242 | F26: =IF('Company Data'!F25<=0,"n/m",('Company Data'!F10-'Company Data'!F25)/'Company Data'!F25) -> 0.25618301 | G26: =IF('Company Data'!G25<=0,"n/m",('Company Data'!G10-'Company Data'!G25)/'Company Data'!G25) -> 0.050056043 | H26: =IF('Company Data'!H25<=0,"n/m",('Company Data'!H10-'Company Data'!H25)/'Company Data'!H25) -> 0.042437021 | I26: =IF('Company Data'!I25<=0,"n/m",('Company Data'!I10-'Company Data'!I25)/'Company Data'!I25) -> 0.079745041 | ... M26: =IF('Company Data'!M25<=0,"n/m",('Company Data'!M10-'Company Data'!M25)/'Company Data'!M25) -> 0.078875444
A27: EBIT | B27: =IF('Company Data'!B26<=0,"n/m",('Company Data'!B11-'Company Data'!B26)/'Company Data'!B26) -> 0.11127183 | C27: =IF('Company Data'!C26<=0,"n/m",('Company Data'!C11-'Company Data'!C26)/'Company Data'!C26) -> -0.081100141 | D27: =IF('Company Data'!D26<=0,"n/m",('Company Data'!D11-'Company Data'!D26)/'Company Data'!D26) -> 0.10727621 | E27: =IF('Company Data'!E26<=0,"n/m",('Company Data'!E11-'Company Data'!E26)/'Company Data'!E26) -> -0.032816312 | F27: =IF('Company Data'!F26<=0,"n/m",('Company Data'!F11-'Company Data'!F26)/'Company Data'!F26) -> -0.033035294 | G27: =IF('Company Data'!G26<=0,"n/m",('Company Data'!G11-'Company Data'!G26)/'Company Data'!G26) -> 0.025661804 | H27: =IF('Company Data'!H26<=0,"n/m",('Company Data'!H11-'Company Data'!H26)/'Company Data'!H26) -> 0.1973952 | I27: =IF('Company Data'!I26<=0,"n/m",('Company Data'!I11-'Company Data'!I26)/'Company Data'!I26) -> -0.11659541 | ... M27: =IF('Company Data'!M26<=0,"n/m",('Company Data'!M11-'Company Data'!M26)/'Company Data'!M26) -> 0.26993525
A28: Net PP&E | B28: =IF('Company Data'!B27<=0,"n/m",('Company Data'!B12-'Company Data'!B27)/'Company Data'!B27) -> 0.12348966 | C28: =IF('Company Data'!C27<=0,"n/m",('Company Data'!C12-'Company Data'!C27)/'Company Data'!C27) -> 0.018132391 | D28: =IF('Company Data'!D27<=0,"n/m",('Company Data'!D12-'Company Data'!D27)/'Company Data'!D27) -> 0.094315776 | E28: =IF('Company Data'!E27<=0,"n/m",('Company Data'!E12-'Company Data'!E27)/'Company Data'!E27) -> 0.054711849 | F28: =IF('Company Data'!F27<=0,"n/m",('Company Data'!F12-'Company Data'!F27)/'Company Data'!F27) -> 0.059755926 | G28: =IF('Company Data'!G27<=0,"n/m",('Company Data'!G12-'Company Data'!G27)/'Company Data'!G27) -> 0.012466844 | H28: =IF('Company Data'!H27<=0,"n/m",('Company Data'!H12-'Company Data'!H27)/'Company Data'!H27) -> -0.066970785 | I28: =IF('Company Data'!I27<=0,"n/m",('Company Data'!I12-'Company Data'!I27)/'Company Data'!I27) -> 0.071963302 | ... M28: =IF('Company Data'!M27<=0,"n/m",('Company Data'!M12-'Company Data'!M27)/'Company Data'!M27) -> 0.039512647
A29: Current assets | B29: =IF('Company Data'!B28<=0,"n/m",('Company Data'!B13-'Company Data'!B28)/'Company Data'!B28) -> 0.068161796 | C29: =IF('Company Data'!C28<=0,"n/m",('Company Data'!C13-'Company Data'!C28)/'Company Data'!C28) -> 0.028323224 | D29: =IF('Company Data'!D28<=0,"n/m",('Company Data'!D13-'Company Data'!D28)/'Company Data'!D28) -> 0.12071483 | E29: =IF('Company Data'!E28<=0,"n/m",('Company Data'!E13-'Company Data'!E28)/'Company Data'!E28) -> 0.085471704 | F29: =IF('Company Data'!F28<=0,"n/m",('Company Data'!F13-'Company Data'!F28)/'Company Data'!F28) -> 0.029325081 | G29: =IF('Company Data'!G28<=0,"n/m",('Company Data'!G13-'Company Data'!G28)/'Company Data'!G28) -> 0.053120452 | H29: =IF('Company Data'!H28<=0,"n/m",('Company Data'!H13-'Company Data'!H28)/'Company Data'!H28) -> 0.19413779 | I29: =IF('Company Data'!I28<=0,"n/m",('Company Data'!I13-'Company Data'!I28)/'Company Data'!I28) -> 0.08220398 | ... M29: =IF('Company Data'!M28<=0,"n/m",('Company Data'!M13-'Company Data'!M28)/'Company Data'!M28) -> 0.11418123
A30: Current liabilities | B30: =IF('Company Data'!B29<=0,"n/m",('Company Data'!B14-'Company Data'!B29)/'Company Data'!B29) -> 0.11269983 | C30: =IF('Company Data'!C29<=0,"n/m",('Company Data'!C14-'Company Data'!C29)/'Company Data'!C29) -> 0.02072215 | D30: =IF('Company Data'!D29<=0,"n/m",('Company Data'!D14-'Company Data'!D29)/'Company Data'!D29) -> 0.046356869 | E30: =IF('Company Data'!E29<=0,"n/m",('Company Data'!E14-'Company Data'!E29)/'Company Data'!E29) -> 0.1312934 | F30: =IF('Company Data'!F29<=0,"n/m",('Company Data'!F14-'Company Data'!F29)/'Company Data'!F29) -> 0.037639281 | G30: =IF('Company Data'!G29<=0,"n/m",('Company Data'!G14-'Company Data'!G29)/'Company Data'!G29) -> 0.18748817 | H30: =IF('Company Data'!H29<=0,"n/m",('Company Data'!H14-'Company Data'!H29)/'Company Data'!H29) -> -0.15715474 | I30: =IF('Company Data'!I29<=0,"n/m",('Company Data'!I14-'Company Data'!I29)/'Company Data'!I29) -> 0.038939625 | ... M30: =IF('Company Data'!M29<=0,"n/m",('Company Data'!M14-'Company Data'!M29)/'Company Data'!M29) -> 0.035770529
A31: Stockholders’ equity | B31: =IF('Company Data'!B30<=0,"n/m",('Company Data'!B15-'Company Data'!B30)/'Company Data'!B30) -> 0.094535945 | C31: =IF('Company Data'!C30<=0,"n/m",('Company Data'!C15-'Company Data'!C30)/'Company Data'!C30) -> 0.10220919 | D31: =IF('Company Data'!D30<=0,"n/m",('Company Data'!D15-'Company Data'!D30)/'Company Data'!D30) -> 0.2346118 | E31: =IF('Company Data'!E30<=0,"n/m",('Company Data'!E15-'Company Data'!E30)/'Company Data'!E30) -> 0.92966867 | F31: =IF('Company Data'!F30<=0,"n/m",('Company Data'!F15-'Company Data'!F30)/'Company Data'!F30) -> n/m | G31: =IF('Company Data'!G30<=0,"n/m",('Company Data'!G15-'Company Data'!G30)/'Company Data'!G30) -> 0.12502838 | H31: =IF('Company Data'!H30<=0,"n/m",('Company Data'!H15-'Company Data'!H30)/'Company Data'!H30) -> 0.29421468 | I31: =IF('Company Data'!I30<=0,"n/m",('Company Data'!I15-'Company Data'!I30)/'Company Data'!I30) -> 0.13109029 | ... M31: =IF('Company Data'!M30<=0,"n/m",('Company Data'!M15-'Company Data'!M30)/'Company Data'!M30) -> 0.36356503
A32: Pretax income | B32: =IF('Company Data'!B31<=0,"n/m",('Company Data'!B16-'Company Data'!B31)/'Company Data'!B31) -> 0.12011099 | C32: =IF('Company Data'!C31<=0,"n/m",('Company Data'!C16-'Company Data'!C31)/'Company Data'!C31) -> -0.093898498 | D32: =IF('Company Data'!D31<=0,"n/m",('Company Data'!D16-'Company Data'!D31)/'Company Data'!D31) -> 0.11067762 | E32: =IF('Company Data'!E31<=0,"n/m",('Company Data'!E16-'Company Data'!E31)/'Company Data'!E31) -> -0.041430485 | F32: =IF('Company Data'!F31<=0,"n/m",('Company Data'!F16-'Company Data'!F31)/'Company Data'!F31) -> -0.044357041 | G32: =IF('Company Data'!G31<=0,"n/m",('Company Data'!G16-'Company Data'!G31)/'Company Data'!G31) -> 0.0038610039 | H32: =IF('Company Data'!H31<=0,"n/m",('Company Data'!H16-'Company Data'!H31)/'Company Data'!H31) -> 0.22252789 | I32: =IF('Company Data'!I31<=0,"n/m",('Company Data'!I16-'Company Data'!I31)/'Company Data'!I31) -> -0.14247447 | ... M32: =IF('Company Data'!M31<=0,"n/m",('Company Data'!M16-'Company Data'!M31)/'Company Data'!M31) -> 0.3278231
A33: Tax provision | B33: =IF('Company Data'!B32<=0,"n/m",('Company Data'!B17-'Company Data'!B32)/'Company Data'!B32) -> 0.17018856 | C33: =IF('Company Data'!C32<=0,"n/m",('Company Data'!C17-'Company Data'!C32)/'Company Data'!C32) -> -0.092307692 | D33: =IF('Company Data'!D32<=0,"n/m",('Company Data'!D17-'Company Data'!D32)/'Company Data'!D32) -> 0.145807 | E33: =IF('Company Data'!E32<=0,"n/m",('Company Data'!E17-'Company Data'!E32)/'Company Data'!E32) -> -0.033478261 | F33: =IF('Company Data'!F32<=0,"n/m",('Company Data'!F17-'Company Data'!F32)/'Company Data'!F32) -> -0.046903461 | G33: =IF('Company Data'!G32<=0,"n/m",('Company Data'!G17-'Company Data'!G32)/'Company Data'!G32) -> 0.18918919 | H33: =IF('Company Data'!H32<=0,"n/m",('Company Data'!H17-'Company Data'!H32)/'Company Data'!H32) -> 0.17398441 | I33: =IF('Company Data'!I32<=0,"n/m",('Company Data'!I17-'Company Data'!I32)/'Company Data'!I32) -> -0.15991379 | ... M33: =IF('Company Data'!M32<=0,"n/m",('Company Data'!M17-'Company Data'!M32)/'Company Data'!M32) -> -0.017485429
A34: Net working capital | B34: =IF(('Company Data'!B28-'Company Data'!B29)<=0,"n/m",(('Company Data'!B13-'Company Data'!B14)-('Company Data'!B28-'Company Data'!B29))/('Company Data'!B28-'Company Data'!B29)) -> n/m | C34: =IF(('Company Data'!C28-'Company Data'!C29)<=0,"n/m",(('Company Data'!C13-'Company Data'!C14)-('Company Data'!C28-'Company Data'!C29))/('Company Data'!C28-'Company Data'!C29)) -> n/m | D34: =IF(('Company Data'!D28-'Company Data'!D29)<=0,"n/m",(('Company Data'!D13-'Company Data'!D14)-('Company Data'!D28-'Company Data'!D29))/('Company Data'!D28-'Company Data'!D29)) -> n/m | E34: =IF(('Company Data'!E28-'Company Data'!E29)<=0,"n/m",(('Company Data'!E13-'Company Data'!E14)-('Company Data'!E28-'Company Data'!E29))/('Company Data'!E28-'Company Data'!E29)) -> -0.34910655 | F34: =IF(('Company Data'!F28-'Company Data'!F29)<=0,"n/m",(('Company Data'!F13-'Company Data'!F14)-('Company Data'!F28-'Company Data'!F29))/('Company Data'!F28-'Company Data'!F29)) -> -0.068082448 | G34: =IF(('Company Data'!G28-'Company Data'!G29)<=0,"n/m",(('Company Data'!G13-'Company Data'!G14)-('Company Data'!G28-'Company Data'!G29))/('Company Data'!G28-'Company Data'!G29)) -> -0.057830572 | H34: =IF(('Company Data'!H28-'Company Data'!H29)<=0,"n/m",(('Company Data'!H13-'Company Data'!H14)-('Company Data'!H28-'Company Data'!H29))/('Company Data'!H28-'Company Data'!H29)) -> 12.052139 | I34: =IF(('Company Data'!I28-'Company Data'!I29)<=0,"n/m",(('Company Data'!I13-'Company Data'!I14)-('Company Data'!I28-'Company Data'!I29))/('Company Data'!I28-'Company Data'!I29)) -> n/m | ... M34: =IF(('Company Data'!M28-'Company Data'!M29)<=0,"n/m",(('Company Data'!M13-'Company Data'!M14)-('Company Data'!M28-'Company Data'!M29))/('Company Data'!M28-'Company Data'!M29)) -> n/m

Sheet Ratios
A1: Module 2 — financial ratios
A3: Company | B3: Walmart | C3: Target | D3: Costco | E3: Home Depot | F3: Lowe’s | G3: Nike | H3: Coca-Cola | I3: PepsiCo | J3: Procter & Gamble | K3: Starbucks | L3: YUM! Brands | M3: Delta Air Lines
A4: Ticker | B4: WMT | C4: TGT | D4: COST | E4: HD | F4: LOW | G4: NKE | H4: KO | I4: PEP | J4: PG | K4: SBUX | L4: YUM | M4: DAL
A5: Current annual period | B5: 46053 | C5: 46053 | D5: 45900 | E5: 46053 | F5: 46053 | G5: 46173 | H5: 46022 | I5: 46022 | J5: 46203 | K5: 45930 | L5: 46022 | M5: 46022
A6: Profitability
A7: Gross margin | B7: =IF(COUNT(B84,B77)<2,"n/a",IF(B77=0,"n/m",B84/B77)) -> 0.249267 | C7: =IF(COUNT(C84,C77)<2,"n/a",IF(C77=0,"n/m",C84/C77)) -> 0.27933766 | D7: =IF(COUNT(D84,D77)<2,"n/a",IF(D77=0,"n/m",D84/D77)) -> 0.12843207 | E7: =IF(COUNT(E84,E77)<2,"n/a",IF(E77=0,"n/m",E84/E77)) -> 0.33315521 | F7: =IF(COUNT(F84,F77)<2,"n/a",IF(F77=0,"n/m",F84/F77)) -> 0.33475883 | G7: =IF(COUNT(G84,G77)<2,"n/a",IF(G77=0,"n/m",G84/G77)) -> 0.42913488 | H7: =IF(COUNT(H84,H77)<2,"n/a",IF(H77=0,"n/m",H84/H77)) -> 0.61625748 | I7: =IF(COUNT(I84,I77)<2,"n/a",IF(I77=0,"n/m",I84/I77)) -> 0.54148523 | ... M7: =IF(COUNT(M84,M77)<2,"n/a",IF(M77=0,"n/m",M84/M77)) -> 0.24165141
A8: Net profit margin | B8: =IF(COUNT(B78,B77)<2,"n/a",IF(B77=0,"n/m",B78/B77)) -> 0.030698452 | C8: =IF(COUNT(C78,C77)<2,"n/a",IF(C77=0,"n/m",C78/C77)) -> 0.035359801 | D8: =IF(COUNT(D78,D77)<2,"n/a",IF(D77=0,"n/m",D78/D77)) -> 0.029425763 | E8: =IF(COUNT(E78,E77)<2,"n/a",IF(E77=0,"n/m",E78/E77)) -> 0.085959085 | F8: =IF(COUNT(F78,F77)<2,"n/a",IF(F77=0,"n/m",F78/F77)) -> 0.077115639 | G8: =IF(COUNT(G78,G77)<2,"n/a",IF(G77=0,"n/m",G78/G77)) -> 0.066985646 | H8: =IF(COUNT(H78,H77)<2,"n/a",IF(H77=0,"n/m",H78/H77)) -> 0.27339855 | I8: =IF(COUNT(I78,I77)<2,"n/a",IF(I77=0,"n/m",I78/I77)) -> 0.087729571 | ... M8: =IF(COUNT(M78,M77)<2,"n/a",IF(M77=0,"n/m",M78/M77)) -> 0.078988069
A9: ROA | B9: =IF(COUNT(B78,B86,B79)<3,"n/a",IF(B79=0,"n/m",(B78+B86)/B79)) -> 0.086739641 | C9: =IF(COUNT(C78,C86,C79)<3,"n/a",IF(C79=0,"n/m",(C78+C86)/C79)) -> 0.069759623 | D9: =IF(COUNT(D78,D86,D79)<3,"n/a",IF(D79=0,"n/m",(D78+D86)/D79)) -> 0.10704419 | E9: =IF(COUNT(E78,E86,E79)<3,"n/a",IF(E79=0,"n/m",(E78+E86)/E79)) -> 0.15764784 | F9: =IF(COUNT(F78,F86,F79)<3,"n/a",IF(F79=0,"n/m",(F78+F86)/F79)) -> 0.15109707 | G9: =IF(COUNT(G78,G86,G79)<3,"n/a",IF(G79=0,"n/m",(G78+G86)/G79)) -> 0.086852382 | H9: =IF(COUNT(H78,H86,H79)<3,"n/a",IF(H79=0,"n/m",(H78+H86)/H79)) -> 0.14082774 | I9: =IF(COUNT(I78,I86,I79)<3,"n/a",IF(I79=0,"n/m",(I78+I86)/I79)) -> 0.087160961 | ... M9: =IF(COUNT(M78,M86,M79)<3,"n/a",IF(M79=0,"n/m",(M78+M86)/M79)) -> 0.069899283
A10: ROE | B10: =IF(COUNT(B78,B80)<2,"n/a",IF(B80=0,"n/m",B78/B80)) -> 0.21977173 | C10: =IF(COUNT(C78,C80)<2,"n/a",IF(C80=0,"n/m",C78/C80)) -> 0.22919889 | D10: =IF(COUNT(D78,D80)<2,"n/a",IF(D80=0,"n/m",D78/D80)) -> 0.27770539 | E10: =IF(COUNT(E78,E80)<2,"n/a",IF(E80=0,"n/m",E78/E80)) -> 1.1048154 | F10: =IF(COUNT(F78,F80)<2,"n/a",IF(F80=0,"n/m",F78/F80)) -> -0.67096904 | G10: =IF(COUNT(G78,G80)<2,"n/a",IF(G80=0,"n/m",G78/G80)) -> 0.20908174 | H10: =IF(COUNT(H78,H80)<2,"n/a",IF(H80=0,"n/m",H78/H80)) -> 0.40744195 | I10: =IF(COUNT(I78,I80)<2,"n/a",IF(I80=0,"n/m",I78/I80)) -> 0.4038028 | ... M10: =IF(COUNT(M78,M80)<2,"n/a",IF(M80=0,"n/m",M78/M80)) -> 0.24001343
A12: Liquidity
A13: Current ratio | B13: =IF(COUNT(B82,B83)<2,"n/a",IF(B83=0,"n/m",B82/B83)) -> 0.78975332 | C13: =IF(COUNT(C82,C83)<2,"n/a",IF(C83=0,"n/m",C82/C83)) -> 0.94229863 | D13: =IF(COUNT(D82,D83)<2,"n/a",IF(D83=0,"n/m",D82/D83)) -> 1.0342783 | E13: =IF(COUNT(E82,E83)<2,"n/a",IF(E83=0,"n/m",E82/E83)) -> 1.0606649 | F13: =IF(COUNT(F82,F83)<2,"n/a",IF(F83=0,"n/m",F82/F83)) -> 1.0766583 | G13: =IF(COUNT(G82,G83)<2,"n/a",IF(G83=0,"n/m",G82/G83)) -> 1.9608671 | H13: =IF(COUNT(H82,H83)<2,"n/a",IF(H83=0,"n/m",H82/H83)) -> 1.458766 | I13: =IF(COUNT(I82,I83)<2,"n/a",IF(I83=0,"n/m",I82/I83)) -> 0.85303992 | ... M13: =IF(COUNT(M82,M83)<2,"n/a",IF(M83=0,"n/m",M82/M83)) -> 0.39704605
A14: Quick ratio | B14: =IF(COUNT(B89,B90,B83)<3,"n/a",IF(B83=0,"n/m",(B89+B90)/B83)) -> 0.20377039 | C14: =IF(COUNT(C89,C90,C83)<3,"n/a",IF(C83=0,"n/m",(C89+C90)/C83)) -> 0.31808761 | D14: =IF(COUNT(D89,D90,D83)<3,"n/a",IF(D83=0,"n/m",(D89+D90)/D83)) -> 0.49819446 | E14: =IF(COUNT(E89,E90,E83)<3,"n/a",IF(E83=0,"n/m",(E89+E90)/E83)) -> 0.19797064 | F14: =IF(COUNT(F89,F90,F83)<3,"n/a",IF(F83=0,"n/m",(F89+F90)/F83)) -> 0.10645841 | G14: =IF(COUNT(G89,G90,G83)<3,"n/a",IF(G83=0,"n/m",(G89+G90)/G83)) -> 1.1921575 | H14: =IF(COUNT(H89,H90,H83)<3,"n/a",IF(H83=0,"n/m",(H89+H90)/H83)) -> 0.8854847 | I14: =IF(COUNT(I89,I90,I83)<3,"n/a",IF(I83=0,"n/m",(I89+I90)/I83)) -> 0.57364791 | ... M14: =IF(COUNT(M89,M90,M83)<3,"n/a",IF(M83=0,"n/m",(M89+M90)/M83)) -> 0.2591949
A16: Leverage
A17: Debt / equity | B17: =IF(COUNT(B87,B80)<2,"n/a",IF(B80=0,"n/m",B87/B80)) -> 0.67352962 | C17: =IF(COUNT(C87,C80)<2,"n/a",IF(C80=0,"n/m",C87/C80)) -> 1.2551809 | D17: =IF(COUNT(D87,D80)<2,"n/a",IF(D80=0,"n/m",D87/D80)) -> 0.28024277 | E17: =IF(COUNT(E87,E80)<2,"n/a",IF(E80=0,"n/m",E87/E80)) -> 5.1002888 | F17: =IF(COUNT(F87,F80)<2,"n/a",IF(F80=0,"n/m",F87/F80)) -> -4.5050923 | G17: =IF(COUNT(G87,G80)<2,"n/a",IF(G80=0,"n/m",G87/G80)) -> 0.74221325 | H17: =IF(COUNT(H87,H80)<2,"n/a",IF(H80=0,"n/m",H87/H80)) -> 1.4141565 | I17: =IF(COUNT(I87,I80)<2,"n/a",IF(I80=0,"n/m",I87/I80)) -> 2.4454082 | ... M17: =IF(COUNT(M87,M80)<2,"n/a",IF(M80=0,"n/m",M87/M80)) -> 0.97223421
A18: Equity multiplier | B18: =IF(COUNT(B79,B80)<2,"n/a",IF(B80=0,"n/m",B79/B80)) -> 2.8576247 | C18: =IF(COUNT(C79,C80)<2,"n/a",IF(C80=0,"n/m",C79/C80)) -> 3.6801732 | D18: =IF(COUNT(D79,D80)<2,"n/a",IF(D80=0,"n/m",D79/D80)) -> 2.643636 | E18: =IF(COUNT(E79,E80)<2,"n/a",IF(E80=0,"n/m",E79/E80)) -> 8.2022165 | F18: =IF(COUNT(F79,F80)<2,"n/a",IF(F80=0,"n/m",F79/F80)) -> -5.4597156 | G18: =IF(COUNT(G79,G80)<2,"n/a",IF(G80=0,"n/m",G79/G80)) -> 2.583922 | H18: =IF(COUNT(H79,H80)<2,"n/a",IF(H80=0,"n/m",H79/H80)) -> 3.2582921 | I18: =IF(COUNT(I79,I80)<2,"n/a",IF(I80=0,"n/m",I79/I80)) -> 5.2631089 | ... M18: =IF(COUNT(M79,M80)<2,"n/a",IF(M80=0,"n/m",M79/M80)) -> 3.8995348
A19: Interest coverage | B19: =IF(COUNT(B81,B86)<2,"n/a",IF(B86=0,"n/m",B81/B86)) -> 11.528403 | C19: =IF(COUNT(C81,C86)<2,"n/a",IF(C86=0,"n/m",C81/C86)) -> 11.71236 | D19: =IF(COUNT(D81,D86)<2,"n/a",IF(D86=0,"n/m",D81/D86)) -> 71.246753 | E19: =IF(COUNT(E81,E86)<2,"n/a",IF(E86=0,"n/m",E81/E86)) -> 8.712272 | F19: =IF(COUNT(F81,F86)<2,"n/a",IF(F86=0,"n/m",F81/F86)) -> 6.7282253 | G19: =IF(COUNT(G81,G86)<2,"n/a",IF(G86=0,"n/m",G81/G86)) -> 16.653509 | H19: =IF(COUNT(H81,H86)<2,"n/a",IF(H86=0,"n/m",H81/H86)) -> 10.67231 | I19: =IF(COUNT(I81,I86)<2,"n/a",IF(I86=0,"n/m",I81/I86)) -> 10.138269 | ... M19: =IF(COUNT(M81,M86)<2,"n/a",IF(M86=0,"n/m",M81/M86)) -> 10.108984
A21: Efficiency
A22: Asset turnover | B22: =IF(COUNT(B77,B79)<2,"n/a",IF(B79=0,"n/m",B77/B79)) -> 2.5052447 | C22: =IF(COUNT(C77,C79)<2,"n/a",IF(C79=0,"n/m",C77/C79)) -> 1.7613044 | D22: =IF(COUNT(D77,D79)<2,"n/a",IF(D79=0,"n/m",D77/D79)) -> 3.5698907 | E22: =IF(COUNT(E77,E79)<2,"n/a",IF(E79=0,"n/m",E77/E79)) -> 1.5669918 | F22: =IF(COUNT(F77,F79)<2,"n/a",IF(F79=0,"n/m",F77/F79)) -> 1.5936392 | G22: =IF(COUNT(G77,G79)<2,"n/a",IF(G79=0,"n/m",G77/G79)) -> 1.2079667 | H22: =IF(COUNT(H77,H79)<2,"n/a",IF(H79=0,"n/m",H77/H79)) -> 0.45738246 | I22: =IF(COUNT(I77,I79)<2,"n/a",IF(I79=0,"n/m",I77/I79)) -> 0.87454259 | ... M22: =IF(COUNT(M77,M79)<2,"n/a",IF(M79=0,"n/m",M77/M79)) -> 0.77922206
A23: Inventory turnover | B23: =IF(COUNT(B85,B88)<2,"n/a",IF(B88=0,"n/m",B85/B88)) -> 9.0974665 | C23: =IF(COUNT(C85,C88)<2,"n/a",IF(C88=0,"n/m",C85/C88)) -> 6.1371099 | D23: =IF(COUNT(D85,D88)<2,"n/a",IF(D88=0,"n/m",D85/D88)) -> 13.241665 | E23: =IF(COUNT(E85,E88)<2,"n/a",IF(E88=0,"n/m",E85/E88)) -> 4.2537088 | F23: =IF(COUNT(F85,F88)<2,"n/a",IF(F88=0,"n/m",F85/F88)) -> 3.3179769 | G23: =IF(COUNT(G85,G88)<2,"n/a",IF(G88=0,"n/m",G85/G88)) -> 3.5311292 | H23: =IF(COUNT(H85,H88)<2,"n/a",IF(H88=0,"n/m",H85/H88)) -> 4.1575141 | I23: =IF(COUNT(I85,I88)<2,"n/a",IF(I88=0,"n/m",I85/I88)) -> 7.3680068 | ... M23: =IF(COUNT(M85,M88)<2,"n/a",IF(M88=0,"n/m",M85/M88)) -> 30.013741
A27: Prior annual period | B27: 45688 | C27: 45688 | D27: 45535 | E27: 45688 | F27: 45688 | G27: 45808 | H27: 45657 | I27: 45657 | J27: 45838 | K27: 45565 | L27: 45657 | M27: 45657
A28: Profitability
A29: Gross margin | B29: =IF(COUNT(B102,B95)<2,"n/a",IF(B95=0,"n/m",B102/B95)) -> 0.24851061 | C29: =IF(COUNT(C102,C95)<2,"n/a",IF(C95=0,"n/m",C102/C95)) -> 0.28211625 | D29: =IF(COUNT(D102,D95)<2,"n/a",IF(D95=0,"n/m",D102/D95)) -> 0.12613331 | E29: =IF(COUNT(E102,E95)<2,"n/a",IF(E95=0,"n/m",E102/E95)) -> 0.3341901 | F29: =IF(COUNT(F102,F95)<2,"n/a",IF(F95=0,"n/m",F102/F95)) -> 0.33316203 | G29: =IF(COUNT(G102,G95)<2,"n/a",IF(G95=0,"n/m",G102/G95)) -> 0.42734674 | H29: =IF(COUNT(H102,H95)<2,"n/a",IF(H95=0,"n/m",H102/H95)) -> 0.61063301 | I29: =IF(COUNT(I102,I95)<2,"n/a",IF(I95=0,"n/m",I102/I95)) -> 0.54553966 | ... M29: =IF(COUNT(M102,M95)<2,"n/a",IF(M95=0,"n/m",M102/M95)) -> 0.246062
A30: Net profit margin | B30: =IF(COUNT(B96,B95)<2,"n/a",IF(B95=0,"n/m",B96/B95)) -> 0.02854101 | C30: =IF(COUNT(C96,C95)<2,"n/a",IF(C95=0,"n/m",C96/C95)) -> 0.038389355 | D30: =IF(COUNT(D96,D95)<2,"n/a",IF(D95=0,"n/m",D96/D95)) -> 0.028952302 | E30: =IF(COUNT(E96,E95)<2,"n/a",IF(E95=0,"n/m",E96/E95)) -> 0.092819439 | F30: =IF(COUNT(F96,F95)<2,"n/a",IF(F95=0,"n/m",F96/F95)) -> 0.083144107 | G30: =IF(COUNT(G96,G95)<2,"n/a",IF(G95=0,"n/m",G96/G95)) -> 0.069511326 | H30: =IF(COUNT(H96,H95)<2,"n/a",IF(H95=0,"n/m",H96/H95)) -> 0.2258983 | I30: =IF(COUNT(I96,I95)<2,"n/a",IF(I95=0,"n/m",I96/I95)) -> 0.10427417 | ... M30: =IF(COUNT(M96,M95)<2,"n/a",IF(M95=0,"n/m",M96/M95)) -> 0.056080982
A31: ROA | B31: =IF(COUNT(B96,B104,B97)<3,"n/a",IF(B97=0,"n/m",(B96+B104)/B97)) -> 0.084977168 | C31: =IF(COUNT(C96,C104,C97)<3,"n/a",IF(C97=0,"n/m",(C96+C104)/C97)) -> 0.07793107 | D31: =IF(COUNT(D96,D104,D97)<3,"n/a",IF(D97=0,"n/m",(D96+D104)/D97)) -> 0.10791769 | E31: =IF(COUNT(E96,E104,E97)<3,"n/a",IF(E97=0,"n/m",(E96+E104)/E97)) -> 0.17818537 | F31: =IF(COUNT(F96,F104,F97)<3,"n/a",IF(F97=0,"n/m",(F96+F104)/F97)) -> 0.19555937 | G31: =IF(COUNT(G96,G104,G97)<3,"n/a",IF(G97=0,"n/m",(G96+G104)/G97)) -> 0.096120725 | H31: =IF(COUNT(H96,H104,H97)<3,"n/a",IF(H97=0,"n/m",(H96+H104)/H97)) -> 0.12219913 | I31: =IF(COUNT(I96,I104,I97)<3,"n/a",IF(I97=0,"n/m",(I96+I104)/I97)) -> 0.10553249 | ... M31: =IF(COUNT(M96,M104,M97)<3,"n/a",IF(M97=0,"n/m",(M96+M104)/M97)) -> 0.055776681
A32: ROE | B32: =IF(COUNT(B96,B98)<2,"n/a",IF(B98=0,"n/m",B96/B98)) -> 0.21355191 | C32: =IF(COUNT(C96,C98)<2,"n/a",IF(C98=0,"n/m",C96/C98)) -> 0.2789445 | D32: =IF(COUNT(D96,D98)<2,"n/a",IF(D98=0,"n/m",D96/D98)) -> 0.31187029 | E32: =IF(COUNT(E96,E98)<2,"n/a",IF(E98=0,"n/m",E96/E98)) -> 2.2298193 | F32: =IF(COUNT(F96,F98)<2,"n/a",IF(F98=0,"n/m",F96/F98)) -> -0.48886234 | G32: =IF(COUNT(G96,G98)<2,"n/a",IF(G98=0,"n/m",G96/G98)) -> 0.2436237 | H32: =IF(COUNT(H96,H98)<2,"n/a",IF(H98=0,"n/m",H96/H98)) -> 0.42770357 | I32: =IF(COUNT(I96,I98)<2,"n/a",IF(I98=0,"n/m",I96/I98)) -> 0.53090183 | ... M32: =IF(COUNT(M96,M98)<2,"n/a",IF(M98=0,"n/m",M96/M98)) -> 0.22605113
A34: Liquidity
A35: Current ratio | B35: =IF(COUNT(B100,B101)<2,"n/a",IF(B101=0,"n/m",B100/B101)) -> 0.82268285 | C35: =IF(COUNT(C100,C101)<2,"n/a",IF(C101=0,"n/m",C100/C101)) -> 0.93533343 | D35: =IF(COUNT(D100,D101)<2,"n/a",IF(D101=0,"n/m",D100/D101)) -> 0.96565531 | E35: =IF(COUNT(E100,E101)<2,"n/a",IF(E101=0,"n/m",E100/E101)) -> 1.1054394 | F35: =IF(COUNT(F100,F101)<2,"n/a",IF(F101=0,"n/m",F100/F101)) -> 1.0853548 | G35: =IF(COUNT(G100,G101)<2,"n/a",IF(G101=0,"n/m",G100/G101)) -> 2.2110543 | H35: =IF(COUNT(H100,H101)<2,"n/a",IF(H101=0,"n/m",H100/H101)) -> 1.0296249 | I35: =IF(COUNT(I100,I101)<2,"n/a",IF(I101=0,"n/m",I100/I101)) -> 0.81893709 | ... M35: =IF(COUNT(M100,M101)<2,"n/a",IF(M101=0,"n/m",M100/M101)) -> 0.36910386
A36: Quick ratio | B36: =IF(COUNT(B107,B108,B101)<3,"n/a",IF(B101=0,"n/m",(B107+B108)/B101)) -> 0.1968442 | C36: =IF(COUNT(C107,C108,C101)<3,"n/a",IF(C101=0,"n/m",(C107+C108)/C101)) -> 0.27693639 | D36: =IF(COUNT(D107,D108,D101)<3,"n/a",IF(D101=0,"n/m",(D107+D108)/D101)) -> 0.39095985 | E36: =IF(COUNT(E107,E108,E101)<3,"n/a",IF(E101=0,"n/m",(E107+E108)/E101)) -> 0.20857611 | F36: =IF(COUNT(F107,F108,F101)<3,"n/a",IF(F101=0,"n/m",(F107+F108)/F101)) -> 0.098896412 | G36: =IF(COUNT(G107,G108,G101)<3,"n/a",IF(G101=0,"n/m",(G107+G108)/G101)) -> 1.3125118 | H36: =IF(COUNT(H107,H108,H101)<3,"n/a",IF(H101=0,"n/m",(H107+H108)/H101)) -> 0.71844429 | I36: =IF(COUNT(I107,I108,I101)<3,"n/a",IF(I101=0,"n/m",(I107+I108)/I101)) -> 0.56294394 | ... M36: =IF(COUNT(M107,M108,M101)<3,"n/a",IF(M101=0,"n/m",(M107+M108)/M101)) -> 0.23595801
A38: Leverage
A39: Debt / equity | B39: =IF(COUNT(B105,B98)<2,"n/a",IF(B98=0,"n/m",B105/B98)) -> 0.66049905 | C39: =IF(COUNT(C105,C98)<2,"n/a",IF(C98=0,"n/m",C105/C98)) -> 1.3551752 | D39: =IF(COUNT(D105,D98)<2,"n/a",IF(D98=0,"n/m",D105/D98)) -> 0.34582169 | E39: =IF(COUNT(E105,E98)<2,"n/a",IF(E98=0,"n/m",E105/E98)) -> 9.3810241 | F39: =IF(COUNT(F105,F98)<2,"n/a",IF(F98=0,"n/m",F105/F98)) -> -2.7881386 | G39: =IF(COUNT(G105,G98)<2,"n/a",IF(G98=0,"n/m",G105/G98)) -> 0.83349731 | H39: =IF(COUNT(H105,H98)<2,"n/a",IF(H98=0,"n/m",H105/H98)) -> 1.7911973 | I39: =IF(COUNT(I105,I98)<2,"n/a",IF(I98=0,"n/m",I105/I98)) -> 2.4914362 | ... M39: =IF(COUNT(M105,M98)<2,"n/a",IF(M98=0,"n/m",M105/M98)) -> 1.4889819
A40: Equity multiplier | B40: =IF(COUNT(B97,B98)<2,"n/a",IF(B98=0,"n/m",B97/B98)) -> 2.8657774 | C40: =IF(COUNT(C97,C98)<2,"n/a",IF(C98=0,"n/m",C97/C98)) -> 3.9389745 | D40: =IF(COUNT(D97,D98)<2,"n/a",IF(D98=0,"n/m",D97/D98)) -> 2.9561849 | E40: =IF(COUNT(E97,E98)<2,"n/a",IF(E98=0,"n/m",E97/E98)) -> 14.475753 | F40: =IF(COUNT(F97,F98)<2,"n/a",IF(F98=0,"n/m",F97/F98)) -> -3.0287401 | G40: =IF(COUNT(G97,G98)<2,"n/a",IF(G98=0,"n/m",G97/G98)) -> 2.7684099 | H40: =IF(COUNT(H97,H98)<2,"n/a",IF(H98=0,"n/m",H97/H98)) -> 4.0452607 | I40: =IF(COUNT(I97,I98)<2,"n/a",IF(I98=0,"n/m",I97/I98)) -> 5.5133862 | ... M40: =IF(COUNT(M97,M98)<2,"n/a",IF(M98=0,"n/m",M97/M98)) -> 4.9285294
A41: Interest coverage | B41: =IF(COUNT(B99,B104)<2,"n/a",IF(B104=0,"n/m",B99/B104)) -> 10.644062 | C41: =IF(COUNT(C99,C104)<2,"n/a",IF(C104=0,"n/m",C99/C104)) -> 13.800487 | D41: =IF(COUNT(D99,D104)<2,"n/a",IF(D104=0,"n/m",D99/D104)) -> 58.633136 | E41: =IF(COUNT(E99,E104)<2,"n/a",IF(E104=0,"n/m",E99/E104)) -> 9.3610513 | F41: =IF(COUNT(F99,F104)<2,"n/a",IF(F104=0,"n/m",F99/F104)) -> 7.2180707 | G41: =IF(COUNT(G99,G104)<2,"n/a",IF(G104=0,"n/m",G99/G104)) -> 12.464646 | H41: =IF(COUNT(H99,H104)<2,"n/a",IF(H104=0,"n/m",H99/H104)) -> 8.9021739 | I41: =IF(COUNT(I99,I104)<2,"n/a",IF(I104=0,"n/m",I99/I104)) -> 13.998912 | ... M41: =IF(COUNT(M99,M104)<2,"n/a",IF(M104=0,"n/m",M99/M104)) -> 7.2356091
A43: Efficiency
A44: Asset turnover | B44: =IF(COUNT(B95,B97)<2,"n/a",IF(B97=0,"n/m",B95/B97)) -> 2.6109085 | C44: =IF(COUNT(C95,C97)<2,"n/a",IF(C97=0,"n/m",C95/C97)) -> 1.8446918 | D44: =IF(COUNT(D95,D97)<2,"n/a",IF(D97=0,"n/m",D95/D97)) -> 3.6438401 | E44: =IF(COUNT(E95,E97)<2,"n/a",IF(E97=0,"n/m",E95/E97)) -> 1.659547 | F44: =IF(COUNT(F95,F97)<2,"n/a",IF(F97=0,"n/m",F95/F97)) -> 1.941302 | G44: =IF(COUNT(G95,G97)<2,"n/a",IF(G97=0,"n/m",G95/G97)) -> 1.2659996 | H44: =IF(COUNT(H95,H97)<2,"n/a",IF(H97=0,"n/m",H95/H97)) -> 0.46804046 | I44: =IF(COUNT(I95,I97)<2,"n/a",IF(I97=0,"n/m",I95/I97)) -> 0.92346205 | ... M44: =IF(COUNT(M95,M97)<2,"n/a",IF(M97=0,"n/m",M95/M97)) -> 0.81785013
A45: Inventory turnover | B45: =IF(COUNT(B103,B106)<2,"n/a",IF(B106=0,"n/m",B103/B106)) -> 9.0680074 | C45: =IF(COUNT(C103,C106)<2,"n/a",IF(C106=0,"n/m",C103/C106)) -> 6.0048666 | D45: =IF(COUNT(D103,D106)<2,"n/a",IF(D106=0,"n/m",D103/D106)) -> 11.924599 | E45: =IF(COUNT(E103,E106)<2,"n/a",IF(E106=0,"n/m",E103/E106)) -> 4.5288474 | F45: =IF(COUNT(F103,F106)<2,"n/a",IF(F106=0,"n/m",F103/F106)) -> 3.2050663 | G45: =IF(COUNT(G103,G106)<2,"n/a",IF(G106=0,"n/m",G103/G106)) -> 3.5410602 | H45: =IF(COUNT(H103,H106)<2,"n/a",IF(H106=0,"n/m",H103/H106)) -> 3.8756345 | I45: =IF(COUNT(I103,I106)<2,"n/a",IF(I106=0,"n/m",I103/I106)) -> 7.86732 | ... M45: =IF(COUNT(M103,M106)<2,"n/a",IF(M106=0,"n/m",M103/M106)) -> 32.545518
A49: Two years prior | B49: 45322 | C49: 45322 | D49: 45169 | E49: 45322 | F49: 45322 | G49: 45443 | H49: 45291 | I49: 45291 | J49: 45473 | K49: 45199 | L49: 45291 | M49: 45291
A50: Profitability
A51: Gross margin | B51: =IF(COUNT(B120,B113)<2,"n/a",IF(B113=0,"n/m",B120/B113)) -> 0.24375391 | C51: =IF(COUNT(C120,C113)<2,"n/a",IF(C113=0,"n/m",C120/C113)) -> 0.27542546 | D51: =IF(COUNT(D120,D113)<2,"n/a",IF(D113=0,"n/m",D120/D113)) -> 0.12259689 | E51: =IF(COUNT(E120,E113)<2,"n/a",IF(E113=0,"n/m",E120/E113)) -> 0.33379402 | F51: =IF(COUNT(F120,F113)<2,"n/a",IF(F113=0,"n/m",F120/F113)) -> 0.33393149 | G51: =IF(COUNT(G120,G113)<2,"n/a",IF(G113=0,"n/m",G120/G113)) -> 0.44560181 | H51: =IF(COUNT(H120,H113)<2,"n/a",IF(H113=0,"n/m",H120/H113)) -> 0.59522665 | I51: =IF(COUNT(I120,I113)<2,"n/a",IF(I113=0,"n/m",I120/I113)) -> 0.54213904 | ... M51: =IF(COUNT(M120,M113)<2,"n/a",IF(M113=0,"n/m",M120/M113)) -> 0.24350537
A52: Net profit margin | B52: =IF(COUNT(B114,B113)<2,"n/a",IF(B113=0,"n/m",B114/B113)) -> 0.023932112 | C52: =IF(COUNT(C114,C113)<2,"n/a",IF(C113=0,"n/m",C114/C113)) -> 0.03852456 | D52: =IF(COUNT(D114,D113)<2,"n/a",IF(D113=0,"n/m",D114/D113)) -> 0.02596888 | E52: =IF(COUNT(E114,E113)<2,"n/a",IF(E113=0,"n/m",E114/E113)) -> 0.09918844 | F52: =IF(COUNT(F114,F113)<2,"n/a",IF(F113=0,"n/m",F114/F113)) -> 0.089445107 | G52: =IF(COUNT(G114,G113)<2,"n/a",IF(G113=0,"n/m",G114/G113)) -> 0.11097699 | H52: =IF(COUNT(H114,H113)<2,"n/a",IF(H113=0,"n/m",H114/H113)) -> 0.23416532 | I52: =IF(COUNT(I114,I113)<2,"n/a",IF(I113=0,"n/m",I114/I113)) -> 0.09920084 | ... M52: =IF(COUNT(M114,M113)<2,"n/a",IF(M113=0,"n/m",M114/M113)) -> 0.079399807
A53: ROA | B53: =IF(COUNT(B114,B122,B115)<3,"n/a",IF(B115=0,"n/m",(B114+B122)/B115)) -> 0.072084279 | C53: =IF(COUNT(C114,C122,C115)<3,"n/a",IF(C115=0,"n/m",(C114+C122)/C115)) -> 0.083821085 | D53: =IF(COUNT(D114,D122,D115)<3,"n/a",IF(D115=0,"n/m",(D114+D122)/D115)) -> 0.093515378 | E53: =IF(COUNT(E114,E122,E115)<3,"n/a",IF(E115=0,"n/m",(E114+E122)/E115)) -> 0.22325885 | F53: =IF(COUNT(F114,F122,F115)<3,"n/a",IF(F115=0,"n/m",(F114+F122)/F115)) -> 0.22033736 | G53: =IF(COUNT(G114,G122,G115)<3,"n/a",IF(G115=0,"n/m",(G114+G122)/G115)) -> 0.15662556 | H53: =IF(COUNT(H114,H122,H115)<3,"n/a",IF(H115=0,"n/m",(H114+H122)/H115)) -> 0.12528786 | I53: =IF(COUNT(I114,I122,I115)<3,"n/a",IF(I115=0,"n/m",(I114+I122)/I115)) -> 0.098442709 | ... M53: =IF(COUNT(M114,M122,M115)<3,"n/a",IF(M115=0,"n/m",(M114+M122)/M115)) -> 0.073909619
...

Sheet DuPont
A1: Module 2 — DuPont analysis
A3: Company | B3: Walmart | C3: Target | D3: Costco | E3: Home Depot | F3: Lowe’s | G3: Nike | H3: Coca-Cola | I3: PepsiCo | J3: Procter & Gamble | K3: Starbucks | L3: YUM! Brands | M3: Delta Air Lines
A4: Ticker | B4: WMT | C4: TGT | D4: COST | E4: HD | F4: LOW | G4: NKE | H4: KO | I4: PEP | J4: PG | K4: SBUX | L4: YUM | M4: DAL
A5: Current annual period | B5: 46053 | C5: 46053 | D5: 45900 | E5: 46053 | F5: 46053 | G5: 46173 | H5: 46022 | I5: 46022 | J5: 46203 | K5: 45930 | L5: 46022 | M5: 46022
A6: Revenue ($m) | B6: ='Company Data'!B6 -> 713163 | C6: ='Company Data'!C6 -> 104780 | D6: ='Company Data'!D6 -> 275235 | E6: ='Company Data'!E6 -> 164683 | F6: ='Company Data'!F6 -> 86286 | G6: ='Company Data'!G6 -> 46398 | H6: ='Company Data'!H6 -> 47941 | I6: ='Company Data'!I6 -> 93925 | ... M6: ='Company Data'!M6 -> 63364
A7: Net income ($m) | B7: ='Company Data'!B7 -> 21893 | C7: ='Company Data'!C7 -> 3705 | D7: ='Company Data'!D7 -> 8099 | E7: ='Company Data'!E7 -> 14156 | F7: ='Company Data'!F7 -> 6654 | G7: ='Company Data'!G7 -> 3108 | H7: ='Company Data'!H7 -> 13107 | I7: ='Company Data'!I7 -> 8240 | ... M7: ='Company Data'!M7 -> 5005
A8: Total assets ($m) | B8: ='Company Data'!B10 -> 284668 | C8: ='Company Data'!C10 -> 59490 | D8: ='Company Data'!D10 -> 77099 | E8: ='Company Data'!E10 -> 105095 | F8: ='Company Data'!F10 -> 54144 | G8: ='Company Data'!G10 -> 38410 | H8: ='Company Data'!H10 -> 104816 | I8: ='Company Data'!I10 -> 107399 | ... M8: ='Company Data'!M10 -> 81317
A9: Stockholders’ equity ($m) | B9: ='Company Data'!B15 -> 99617 | C9: ='Company Data'!C15 -> 16165 | D9: ='Company Data'!D15 -> 29164 | E9: ='Company Data'!E15 -> 12813 | F9: ='Company Data'!F15 -> -9917 | G9: ='Company Data'!G15 -> 14865 | H9: ='Company Data'!H15 -> 32169 | I9: ='Company Data'!I15 -> 20406 | ... M9: ='Company Data'!M15 -> 20853
A11: Net profit margin | B11: =IF(B6=0,"n/m",B7/B6) -> 0.030698452 | C11: =IF(C6=0,"n/m",C7/C6) -> 0.035359801 | D11: =IF(D6=0,"n/m",D7/D6) -> 0.029425763 | E11: =IF(E6=0,"n/m",E7/E6) -> 0.085959085 | F11: =IF(F6=0,"n/m",F7/F6) -> 0.077115639 | G11: =IF(G6=0,"n/m",G7/G6) -> 0.066985646 | H11: =IF(H6=0,"n/m",H7/H6) -> 0.27339855 | I11: =IF(I6=0,"n/m",I7/I6) -> 0.087729571 | ... M11: =IF(M6=0,"n/m",M7/M6) -> 0.078988069
A12: Asset turnover | B12: =IF(B8=0,"n/m",B6/B8) -> 2.5052447 | C12: =IF(C8=0,"n/m",C6/C8) -> 1.7613044 | D12: =IF(D8=0,"n/m",D6/D8) -> 3.5698907 | E12: =IF(E8=0,"n/m",E6/E8) -> 1.5669918 | F12: =IF(F8=0,"n/m",F6/F8) -> 1.5936392 | G12: =IF(G8=0,"n/m",G6/G8) -> 1.2079667 | H12: =IF(H8=0,"n/m",H6/H8) -> 0.45738246 | I12: =IF(I8=0,"n/m",I6/I8) -> 0.87454259 | ... M12: =IF(M8=0,"n/m",M6/M8) -> 0.77922206
A13: Equity multiplier | B13: =IF(B9=0,"n/m",B8/B9) -> 2.8576247 | C13: =IF(C9=0,"n/m",C8/C9) -> 3.6801732 | D13: =IF(D9=0,"n/m",D8/D9) -> 2.643636 | E13: =IF(E9=0,"n/m",E8/E9) -> 8.2022165 | F13: =IF(F9=0,"n/m",F8/F9) -> -5.4597156 | G13: =IF(G9=0,"n/m",G8/G9) -> 2.583922 | H13: =IF(H9=0,"n/m",H8/H9) -> 3.2582921 | I13: =IF(I9=0,"n/m",I8/I9) -> 5.2631089 | ... M13: =IF(M9=0,"n/m",M8/M9) -> 3.8995348
A14: ROE | B14: =IF(OR(B6=0,B8=0,B9=0),"n/m",B11*B12*B13) -> 0.21977173 | C14: =IF(OR(C6=0,C8=0,C9=0),"n/m",C11*C12*C13) -> 0.22919889 | D14: =IF(OR(D6=0,D8=0,D9=0),"n/m",D11*D12*D13) -> 0.27770539 | E14: =IF(OR(E6=0,E8=0,E9=0),"n/m",E11*E12*E13) -> 1.1048154 | F14: =IF(OR(F6=0,F8=0,F9=0),"n/m",F11*F12*F13) -> -0.67096904 | G14: =IF(OR(G6=0,G8=0,G9=0),"n/m",G11*G12*G13) -> 0.20908174 | H14: =IF(OR(H6=0,H8=0,H9=0),"n/m",H11*H12*H13) -> 0.40744195 | I14: =IF(OR(I6=0,I8=0,I9=0),"n/m",I11*I12*I13) -> 0.4038028 | ... M14: =IF(OR(M6=0,M8=0,M9=0),"n/m",M11*M12*M13) -> 0.24001343
A17: Prior annual period | B17: 45688 | C17: 45688 | D17: 45535 | E17: 45688 | F17: 45688 | G17: 45808 | H17: 45657 | I17: 45657 | J17: 45838 | K17: 45565 | L17: 45657 | M17: 45657
A18: Revenue ($m) | B18: ='Company Data'!B21 -> 680985 | C18: ='Company Data'!C21 -> 106566 | D18: ='Company Data'!D21 -> 254453 | E18: ='Company Data'!E21 -> 159514 | F18: ='Company Data'!F21 -> 83674 | G18: ='Company Data'!G21 -> 46309 | H18: ='Company Data'!H21 -> 47061 | I18: ='Company Data'!I21 -> 91854 | ... M18: ='Company Data'!M21 -> 61643
A19: Net income ($m) | B19: ='Company Data'!B22 -> 19436 | C19: ='Company Data'!C22 -> 4091 | D19: ='Company Data'!D22 -> 7367 | E19: ='Company Data'!E22 -> 14806 | F19: ='Company Data'!F22 -> 6957 | G19: ='Company Data'!G22 -> 3219 | H19: ='Company Data'!H22 -> 10631 | I19: ='Company Data'!I22 -> 9578 | ... M19: ='Company Data'!M22 -> 3457
A20: Total assets ($m) | B20: ='Company Data'!B25 -> 260823 | C20: ='Company Data'!C25 -> 57769 | D20: ='Company Data'!D25 -> 69831 | E20: ='Company Data'!E25 -> 96119 | F20: ='Company Data'!F25 -> 43102 | G20: ='Company Data'!G25 -> 36579 | H20: ='Company Data'!H25 -> 100549 | I20: ='Company Data'!I25 -> 99467 | ... M20: ='Company Data'!M25 -> 75372
A21: Stockholders’ equity ($m) | B21: ='Company Data'!B30 -> 91013 | C21: ='Company Data'!C30 -> 14666 | D21: ='Company Data'!D30 -> 23622 | E21: ='Company Data'!E30 -> 6640 | F21: ='Company Data'!F30 -> -14231 | G21: ='Company Data'!G30 -> 13213 | H21: ='Company Data'!H30 -> 24856 | I21: ='Company Data'!I30 -> 18041 | ... M21: ='Company Data'!M30 -> 15293
A23: Net profit margin | B23: =IF(B18=0,"n/m",B19/B18) -> 0.02854101 | C23: =IF(C18=0,"n/m",C19/C18) -> 0.038389355 | D23: =IF(D18=0,"n/m",D19/D18) -> 0.028952302 | E23: =IF(E18=0,"n/m",E19/E18) -> 0.092819439 | F23: =IF(F18=0,"n/m",F19/F18) -> 0.083144107 | G23: =IF(G18=0,"n/m",G19/G18) -> 0.069511326 | H23: =IF(H18=0,"n/m",H19/H18) -> 0.2258983 | I23: =IF(I18=0,"n/m",I19/I18) -> 0.10427417 | ... M23: =IF(M18=0,"n/m",M19/M18) -> 0.056080982
A24: Asset turnover | B24: =IF(B20=0,"n/m",B18/B20) -> 2.6109085 | C24: =IF(C20=0,"n/m",C18/C20) -> 1.8446918 | D24: =IF(D20=0,"n/m",D18/D20) -> 3.6438401 | E24: =IF(E20=0,"n/m",E18/E20) -> 1.659547 | F24: =IF(F20=0,"n/m",F18/F20) -> 1.941302 | G24: =IF(G20=0,"n/m",G18/G20) -> 1.2659996 | H24: =IF(H20=0,"n/m",H18/H20) -> 0.46804046 | I24: =IF(I20=0,"n/m",I18/I20) -> 0.92346205 | ... M24: =IF(M20=0,"n/m",M18/M20) -> 0.81785013
A25: Equity multiplier | B25: =IF(B21=0,"n/m",B20/B21) -> 2.8657774 | C25: =IF(C21=0,"n/m",C20/C21) -> 3.9389745 | D25: =IF(D21=0,"n/m",D20/D21) -> 2.9561849 | E25: =IF(E21=0,"n/m",E20/E21) -> 14.475753 | F25: =IF(F21=0,"n/m",F20/F21) -> -3.0287401 | G25: =IF(G21=0,"n/m",G20/G21) -> 2.7684099 | H25: =IF(H21=0,"n/m",H20/H21) -> 4.0452607 | I25: =IF(I21=0,"n/m",I20/I21) -> 5.5133862 | ... M25: =IF(M21=0,"n/m",M20/M21) -> 4.9285294
A26: ROE | B26: =IF(OR(B18=0,B20=0,B21=0),"n/m",B23*B24*B25) -> 0.21355191 | C26: =IF(OR(C18=0,C20=0,C21=0),"n/m",C23*C24*C25) -> 0.2789445 | D26: =IF(OR(D18=0,D20=0,D21=0),"n/m",D23*D24*D25) -> 0.31187029 | E26: =IF(OR(E18=0,E20=0,E21=0),"n/m",E23*E24*E25) -> 2.2298193 | F26: =IF(OR(F18=0,F20=0,F21=0),"n/m",F23*F24*F25) -> -0.48886234 | G26: =IF(OR(G18=0,G20=0,G21=0),"n/m",G23*G24*G25) -> 0.2436237 | H26: =IF(OR(H18=0,H20=0,H21=0),"n/m",H23*H24*H25) -> 0.42770357 | I26: =IF(OR(I18=0,I20=0,I21=0),"n/m",I23*I24*I25) -> 0.53090183 | ... M26: =IF(OR(M18=0,M20=0,M21=0),"n/m",M23*M24*M25) -> 0.22605113
A29: Two years prior | B29: 45322 | C29: 45322 | D29: 45169 | E29: 45322 | F29: 45322 | G29: 45443 | H29: 45291 | I29: 45291 | J29: 45473 | K29: 45199 | L29: 45291 | M29: 45291
A30: Revenue ($m) | B30: 648125 | C30: 107412 | D30: 242290 | E30: 152669 | F30: 86377 | G30: 51362 | H30: 45754 | I30: 91471 | J30: 84039 | K30: 35975.6 | L30: 7076 | M30: 58048
A31: Net income ($m) | B31: 15511 | C31: 4138 | D31: 6292 | E31: 15143 | F31: 7726 | G31: 5700 | H31: 10714 | I31: 9074 | J31: 14879 | K31: 4124.5 | L31: 1597 | M31: 4609
A32: Total assets ($m) | B32: 252399 | C32: 55356 | D32: 68994 | E32: 76530 | F32: 41795 | G32: 38110 | H32: 97703 | I32: 100495 | J32: 122370 | K32: 29445.5 | L32: 6231 | M32: 73644
A33: Stockholders’ equity ($m) | B33: 83861 | C33: 13432 | D33: 25058 | E33: 1044 | F33: -15050 | G33: 14430 | H33: 25941 | I33: 18503 | J33: 50286 | K33: -7994.8 | L33: -7858 | M33: 11105
A35: Net profit margin | B35: =IF(B30=0,"n/m",B31/B30) -> 0.023932112 | C35: =IF(C30=0,"n/m",C31/C30) -> 0.03852456 | D35: =IF(D30=0,"n/m",D31/D30) -> 0.02596888 | E35: =IF(E30=0,"n/m",E31/E30) -> 0.09918844 | F35: =IF(F30=0,"n/m",F31/F30) -> 0.089445107 | G35: =IF(G30=0,"n/m",G31/G30) -> 0.11097699 | H35: =IF(H30=0,"n/m",H31/H30) -> 0.23416532 | I35: =IF(I30=0,"n/m",I31/I30) -> 0.09920084 | ... M35: =IF(M30=0,"n/m",M31/M30) -> 0.079399807
A36: Asset turnover | B36: =IF(B32=0,"n/m",B30/B32) -> 2.5678588 | C36: =IF(C32=0,"n/m",C30/C32) -> 1.9403859 | D36: =IF(D32=0,"n/m",D30/D32) -> 3.5117546 | E36: =IF(E32=0,"n/m",E30/E32) -> 1.9948909 | F36: =IF(F32=0,"n/m",F30/F32) -> 2.0666826 | G36: =IF(G32=0,"n/m",G30/G32) -> 1.3477303 | H36: =IF(H32=0,"n/m",H30/H32) -> 0.46829678 | I36: =IF(I32=0,"n/m",I30/I32) -> 0.91020449 | ... M36: =IF(M32=0,"n/m",M30/M32) -> 0.78822443
A37: Equity multiplier | B37: =IF(B33=0,"n/m",B32/B33) -> 3.0097304 | C37: =IF(C33=0,"n/m",C32/C33) -> 4.1212031 | D37: =IF(D33=0,"n/m",D32/D33) -> 2.7533722 | E37: =IF(E33=0,"n/m",E32/E33) -> 73.304598 | F37: =IF(F33=0,"n/m",F32/F33) -> -2.7770764 | G37: =IF(G33=0,"n/m",G32/G33) -> 2.6410256 | H37: =IF(H33=0,"n/m",H32/H33) -> 3.7663544 | I37: =IF(I33=0,"n/m",I32/I33) -> 5.4312814 | ... M37: =IF(M33=0,"n/m",M32/M33) -> 6.6316074
A38: ROE | B38: =IF(OR(B30=0,B32=0,B33=0),"n/m",B35*B36*B37) -> 0.18496083 | C38: =IF(OR(C30=0,C32=0,C33=0),"n/m",C35*C36*C37) -> 0.30807028 | D38: =IF(OR(D30=0,D32=0,D33=0),"n/m",D35*D36*D37) -> 0.25109745 | E38: =IF(OR(E30=0,E32=0,E33=0),"n/m",E35*E36*E37) -> 14.504789 | F38: =IF(OR(F30=0,F32=0,F33=0),"n/m",F35*F36*F37) -> -0.51335548 | G38: =IF(OR(G30=0,G32=0,G33=0),"n/m",G35*G36*G37) -> 0.3950104 | H38: =IF(OR(H30=0,H32=0,H33=0),"n/m",H35*H36*H37) -> 0.41301415 | I38: =IF(OR(I30=0,I32=0,I33=0),"n/m",I35*I36*I37) -> 0.49040696 | ... M38: =IF(OR(M30=0,M32=0,M33=0),"n/m",M35*M36*M37) -> 0.41503827

Sheet Notes
A1: Notes and sources
A2: Units | B2: Dollar totals are USD millions; shares are millions; basic EPS is dollars per share. Parentheses mean negative values.
A3: Periods | B3: Yahoo annual period labels are retained; fiscal calendars differ and 52/53-week dates may be normalized to month-end.
A4: Basic EPS and shares | B4: Basic EPS is Yahoo BasicEPS. Shares outstanding is year-end OrdinarySharesNumber, excluding treasury shares. It is not the weighted-average share count used to calculate EPS.
A5: Year-over-year changes | B5: Current minus prior. Percentage change divides by the prior value. n/m means a zero or negative prior value makes the usual growth percentage unhelpful; the absolute change is still shown.
A6: Working capital / FCF | B6: Net working capital = current assets − current liabilities. Changes in net PP&E and working capital support the simplified class FCF calculation. Net PP&E change is not capital expenditure.
A7: Tax and equity | B7: For the class FCF exercise, use tax provision / pretax income as the tax assumption. Negative equity needs care when interpreting ROE and leverage.
A8: Source snapshots | B8: Original ten firms and DAL: October 12, 2026. YUM: October 19, 2026. DuPont’s third year comes from the same saved Yahoo annual statements; existing inputs and periods are unchanged.
A10: Yahoo annual field | B10: Classroom input
A11: TotalRevenue | B11: Revenue ($m)
A12: NetIncome | B12: Net income ($m)
A13: BasicEPS | B13: Basic EPS ($/share)
A14: OrdinarySharesNumber | B14: Shares outstanding (m)
... A24: Company | B24: Yahoo statement sources
A25: WMT | B25: Income statement | C25: Balance sheet
A26: TGT | B26: Income statement | C26: Balance sheet
A27: COST | B27: Income statement | C27: Balance sheet
A28: HD | B28: Income statement | C28: Balance sheet
A29: LOW | B29: Income statement | C29: Balance sheet
A30: NKE | B30: Income statement | C30: Balance sheet
A31: KO | B31: Income statement | C31: Balance sheet
A32: PEP | B32: Income statement | C32: Balance sheet
A33: PG | B33: Income statement | C33: Balance sheet
A34: SBUX | B34: Income statement | C34: Balance sheet
A35: YUM | B35: Income statement | C35: Balance sheet
A36: DAL | B36: Income statement | C36: Balance sheet
A37: DuPont | B37: Net profit margin = NI / revenue; asset turnover = revenue / assets; equity multiplier = assets / equity. Their product is ROE = NI / equity.
A38: DuPont balances | B38: Use year-end assets and equity, consistent with this class workbook. Three annual periods are shown for each company; fiscal calendars differ.
A39: DuPont interpretation | B39: Negative equity produces negative ROE even with positive income; it is not an ordinary profitability comparison. A small equity base can produce very large ratios. Zero denominators display n/m.
A41: Ratio | B41: Formula / convention
A42: Gross margin | B42: Gross profit / revenue
A43: Net profit margin | B43: Net income / revenue
A44: ROA | B44: (Net income + interest expense) / total assets — the instructor-notes convention.
A45: ROE | B45: Net income / book equity
A46: Current ratio | B46: Current assets / current liabilities
A47: Quick ratio | B47: (Cash, cash equivalents and short-term investments + accounts receivable) / current liabilities — slide 6.
A48: Debt / equity | B48: Yahoo Total Debt / book equity; includes reported lease obligations. Not total liabilities.
A49: Equity multiplier | B49: Total assets / book equity
... A61: Lowe’s FY2023 10-K | B61: Supplementary source
